Workbook

Sheet Equipment Tree
A1: BPL131
A2: BR4.SRV.CTRLSYS.PLC.BPL131 | B2: BPL131 PLC
A3: BR4.SRV.CTRLSYS.PLC.BPL131.Drop01 | B3: BPL131 Drop 1 - BTY1502DX01
A4: BR4.SRV.CTRLSYS.PLC.BPL131.Drop02 | B4: BPL131 Drop 2 - BSR131DX01
A5: BR4.SRV.CTRLSYS.PLC.BPL131.Drop03 | B5: BPL131 Drop 3 - BTY1502DX03
A6: BR4.SRV.CTRLSYS.PLC.BPL131.Drop04 | B6: BPL131 Drop 4 - BTK2101DX04
A8: BSR131
A9: BR4.SRV.PWR.BSR131 | B9: BSR131 Switchroom
A10: BR4.SRV.PWR.BSR131.AC01 | B10: BSR131 Switchroom - Air Conditioner 1
A11: BR4.SRV.PWR.BSR131.AC01.CB01 | B11: BSR131 Switchroom - Air Conditioner 1 Main Circuit Breaker
A12: BR4.SRV.PWR.BSR131.AC02 | B12: BSR131 Switchroom - Air Conditioner 2
A13: BR4.SRV.PWR.BSR131.AC02.CB01 | B13: BSR131 Switchroom - Air Conditioner 2 Main Circuit Breaker
A14: BR4.SRV.PWR.BSR131.BC01 | B14: BSR131 Switchroom - Battery Charger 1
A15: BR4.SRV.PWR.BSR131.BC01.CB01 | B15: BSR131 Switchroom - Battery Charger 1 Main Circuit Breaker
A16: BR4.SRV.PWR.BSR131.BC02 | B16: BSR131 Switchroom - Battery Charger 2
A17: BR4.SRV.PWR.BSR131.BC02.BACS | B17: BSR131 Switchroom - Battery Charger 2 Battery Management
A18: BR4.SRV.PWR.BSR131.BC02.CB01 | B18: BSR131 Switchroom - Battery Charger 2 Main Circuit Breaker
A19: BR4.SRV.PWR.BSR131.BC02.Cordex | B19: BSR131 Switchroom - Battery Charger 2 Controller
A20: BR4.SRV.PWR.BSR131.BMC131 | B20: BMC131 Motor Control Centre
... A43: BR4.SRV.PWR.BSR131.UP01.UPScale | B43: UP01 - BSR131 UPS
A45: Pumps
A46: BR4.UTILITIES.WATER.BS1.RWD1.BPP1101 | B46: BPP1101 - Raw Water Distribution Pump
A47: BR4.UTILITIES.WATER.BS1.RWD1.BPP1101.FieldIO | B47: BPP1101 - Field I/O
A48: BR4.UTILITIES.WATER.BS1.RWD1.BPP1101.FieldIO.FT01 | B48: BPP1101 - FT01 NPI Raw Water Flowmeter
A49: BR4.UTILITIES.WATER.BS1.RWD1.BPP1101.FieldIO.FT03 | B49: BPP1101 - FT03 NPI/PC3 Supply Flowmeter
A50: BR4.UTILITIES.WATER.BS1.RWD1.BPP1101.FieldIO.PT03 | B50: BPP1101 - PT03 Pump Discharge Pressure
A51: BR4.UTILITIES.WATER.BS1.RWD1.BPP1101.FieldIO.PT10 | B51: BPP1101 - PT10 BS1 Raw Water Distribution Pressure 1
A52: BR4.UTILITIES.WATER.BS1.RWD1.BPP1101.FieldIO.PT11 | B52: BPP1101 - PT11 BS1 Raw Water Distribution Pressure 2
A53: BR4.UTILITIES.WATER.BS1.RWD1.BPP1101.Sub | B53: BPP1101 - Feeder
A54: BR4.UTILITIES.WATER.BS1.RWD1.BPP1101.Sub.CB01 | B54: BPP1101 - Feeder Main Cicuit Breaker
A55: BR4.UTILITIES.WATER.BS1.RWD1.BPP1101.VS01 | B55: BPP1101 - Raw Water Distribution Pump VSD
A56: BR4.UTILITIES.WATER.BS1.RWD1.BPP1102 | B56: BPP1102 - Raw Water Distribution Pump
A57: BR4.UTILITIES.WATER.BS1.RWD1.BPP1102.FieldIO | B57: BPP1102 - Field I/O
... A96: BR4.UTILITIES.WATER.BS1.STD1.BPP1107.VS01 | B96: BPP1107 - Raw Water Transfer Pump VSD
A98: Standpipes
A99: BR4.UTILITIES.WATER.BS1.STD1.BSTD1106 | B99: BSTD1106 - LME Standpipe
A100: BR4.UTILITIES.WATER.BS1.STD1.BSTD1106.FieldIO | B100: BSTD1106 - Field I/O
A101: BR4.UTILITIES.WATER.BS1.STD1.BSTD1106.FieldIO.FT03 | B101: BSTD1106 - FT03 LME Standpipe Flowmeter
A102: BR4.UTILITIES.WATER.BS1.STD1.BSTD1106.FV03 | B102: BSTD1106 - FV03 LME Standpipe Flow Valve
A103: BR4.UTILITIES.WATER.BS1.STD1.BSTD1106.FV03.FieldIO | B103: BSTD1106 - FV03 LME Standpipe Flow Valve Field I/O
...

Sheet Variables
A1: BR4.SRV.CTRLSYS.PLC.BPL131.Drop02 | B1: I | C1: BTY1502DX02CB01_I | D1: BR4_Cluster1 | E1: BPL131 | F1: DIGITAL | G1: %M1000 | H1: West Turkeys Nest DIO Box 2 240VAC BTY1502AX01 Control Supply Circuit Breaker (Q106) Closed | K1: BS1_Tags
A2: BR4.SRV.PWR.BSR131.BMC1311.Sub.CB01 | B2: Hty | C2: BMC1311CB01_Hty | D2: BR4_Cluster1 | E2: BPL131 | F2: DIGITAL | G2: %M10000 | H2: HME Refuelling MCC Main Circuit Breaker (Q103) Open Healthy | K2: BS1_Tags
A3: BR4.SRV.PWR.BSR131.BMC1311.Sub.CB01 | B3: Hty | C3: BMC1311TRP01_Hty | D3: BR4_Cluster1 | E3: BPL131 | F3: DIGITAL | G3: %M10001 | H3: HME Refuelling MCC Main Circuit Breaker Trip Healthy | K3: BS1_Tags
A4: BR4.SRV.PWR.BSR131.BMC1311 | B4: Hty | C4: BMC1311VDC01_Hty | D4: BR4_Cluster1 | E4: BPL131 | F4: DIGITAL | G4: %M10002 | H4: HME Refuelling MCC 24VDC Control Supply (Q155) Failure Healthy | K4: BS1_Tags
A5: BR4.SRV.PWR.BSR131.BMC131.INC01 | B5: Hty | C5: BMC131INC01CB02_Hty | D5: BR4_Cluster1 | E5: BPL131 | F5: DIGITAL | G5: %M10003 | H5: BMC131 Process Bus Incomer Arc Flash Supply (Q204) Open Healthy | K5: BS1_Tags
A6: BR4.SRV.PWR.BSR131.BMC131.INC01 | B6: Hty | C6: BMC131INC01CB03_Hty | D6: BR4_Cluster1 | E6: BPL131 | F6: DIGITAL | G6: %M10004 | H6: BMC131 Process Bus Incomer Circuit Breaker Spring Charge Supply (Q212) Open Healthy | K6: BS1_Tags
A7: BR4.SRV.PWR.BSR131.BMC131.INC01 | B7: Hty | C7: BMC131INC01CB04_Hty | D7: BR4_Cluster1 | E7: BPL131 | F7: DIGITAL | G7: %M10005 | H7: BMC131 Process Bus Incomer Circuit Breaker Trip Supply (Q220) Open Healthy | K7: BS1_Tags
A8: BR4.SRV.PWR.BSR131.BMC131.INC01 | B8: Hty | C8: BMC131INC01CB05_Hty | D8: BR4_Cluster1 | E8: BPL131 | F8: DIGITAL | G8: %M10006 | H8: BMC131 Process Bus Incomer Circuit Breaker 24VDC Cubicle Bus Supply (Q256) Open Healthy | K8: BS1_Tags
A9: BR4.SRV.PWR.BSR131.BMC131.INC01 | B9: Hty | C9: BMC131INC01CB06_Hty | D9: BR4_Cluster1 | E9: BPL131 | F9: DIGITAL | G9: %M10007 | H9: BMC131 Process Bus Incomer 110VDC/24VDC Power Supply (Q215) Open Healthy | K9: BS1_Tags
A10: BR4.SRV.PWR.BSR131.BMC131.INC01 | B10: CB_PwrOK | C10: BMC131INC01PR1_CB_PwrOK | D10: BR4_Cluster1 | E10: BPL131 | F10: DIGITAL | G10: %M10008 | H10: BMC131 Process Bus Incomer Protection Relay Main Power to Drive Healthy | K10: BS1_Tags
A11: BR4.SRV.PWR.BSR131.BMC131.INC01 | B11: CBCls | C11: BMC131INC01PR1_CBCls | D11: BR4_Cluster1 | E11: BPL131 | F11: DIGITAL | G11: %M10009 | H11: BMC131 Process Bus Incomer Protection Relay Circuit Breaker Closed | K11: BS1_Tags
A12: BR4.UTILITIES.WATER.BS1.BTY1502.FieldIO | B12: I | C12: BTY1502DX02VDC01_I | D12: BR4_Cluster1 | E12: BPL131 | F12: DIGITAL | G12: %M1001 | H12: West Turkeys Nest DIO Box 2 24VDC Output Control Supply (Q143) Healthy | K12: BS1_Tags
... A1701: BR4.SRV.CTRLSYS.PLC.BPL131 | B1701: ScnMin | C1701: BPL131_ScnMin | D1701: BR4_Cluster1 | E1701: BPL131 | F1701: INT | G1701: %MW1138 | H1701: NPI Hub PLC CPU Minimum Scan Time (ms) | K1701: BS1_Tags
A1702: BR4.SRV.CTRLSYS.PLC.BPL131 | B1702: ScanTm | C1702: BPL131_ScnVal | D1702: BR4_Cluster1 | E1702: BPL131 | F1702: INT | G1702: %MW1139 | H1702: NPI Hub PLC CPU Last Scan Time (ms) | I1702: 0 | J1702: 1000 | K1702: BS1_Tags
A1703: BR4.SRV.CTRLSYS.PLC.BPL131 | B1703: SysScnAvg | C1703: BPL131_SysScnAvg | D1703: BR4_Cluster1 | E1703: BPL131 | F1703: INT | G1703: %MW1140 | H1703: NPI Hub PLC CPU Average Overhead Scan Time (ms) | K1703: BS1_Tags
A1704: BR4.SRV.CTRLSYS.PLC.BPL131 | B1704: SysScnMax | C1704: BPL131_SysScnMax | D1704: BR4_Cluster1 | E1704: BPL131 | F1704: INT | G1704: %MW1141 | H1704: NPI Hub PLC CPU Maximum Overhead Scan Time (ms) | K1704: BS1_Tags
A1705: BR4.SRV.CTRLSYS.PLC.BPL131 | B1705: SysScnMin | C1705: BPL131_SysScnMin | D1705: BR4_Cluster1 | E1705: BPL131 | F1705: INT | G1705: %MW1142 | H1705: NPI Hub PLC CPU Minimum Overhead Scan Time (ms) | K1705: BS1_Tags
A1706: BR4.SRV.CTRLSYS.PLC.BPL131 | B1706: SysScnVal | C1706: BPL131_SysScnVal | D1706: BR4_Cluster1 | E1706: BPL131 | F1706: INT | G1706: %MW1143 | H1706: NPI Hub PLC CPU Last Overhead Scan Time (ms) | K1706: BS1_Tags
A1707: BR4.SRV.CTRLSYS.PLC.BPL131 | B1707: WD | C1707: BPL131_WD | D1707: BR4_Cluster1 | E1707: BPL131 | F1707: INT | G1707: %MW1144 | H1707: NPI Hub PLC CPU Heart Beat Watchdog | K1707: BS1_Tags
A1708: BR4.SRV.CTRLSYS.PLC.BPL131 | B1708: BPL131PLM0STS2 | C1708: BPL131PLM0STS2 | D1708: BR4_Cluster1 | E1708: BPL131 | F1708: INT | G1708: %MW1145[4] | H1708: NPI Hub PLC CPU RIO Network Status Data | K1708: BS1_Tags
A1709: BR4.UTILITIES.WATER.BS1.RWD1.BPP1101 | B1709: BPP1101DRVSTAT | C1709: BPP1101DRVSTAT | D1709: BR4_Cluster1 | E1709: BPL131 | F1709: INT | G1709: %MW1183 | H1709: Production Plant and NPI Water Supply Pump 1 Status Word | K1709: BS1_Tags
A1710: BR4.UTILITIES.WATER.BS1.RWD1.BPP1102 | B1710: BPP1102DRVSTAT | C1710: BPP1102DRVSTAT | D1710: BR4_Cluster1 | E1710: BPL131 | F1710: INT | G1710: %MW1277 | H1710: Production Plant and NPI Water Supply Pump 2 Status Word | K1710: BS1_Tags
A1711: BR4.UTILITIES.WATER.BS1.RWT.BPP1103 | B1711: BPP1103DRVSTAT | C1711: BPP1103DRVSTAT | D1711: BR4_Cluster1 | E1711: BPL131 | F1711: INT | G1711: %MW1307 | H1711: Water Transfer Pump 1 Status Word | K1711: BS1_Tags
A1712: BR4.UTILITIES.WATER.BS1.RWT.BPP1103.FieldIO.FT03 | B1712: Tot | C1712: BPP1103FT03_Tot | D1712: BR4_Cluster1 | E1712: BPL131 | F1712: INT | G1712: %MW1308[18] | H1712: Water Transfer Pump 1 Flow Rate (m3/h) Flow Totals | K1712: BS1_Tags
A1713: BR4.UTILITIES.WATER.BS1.RWT.BPP1103.FieldIO.FT06 | B1713: Tot | C1713: BPP1103FT06_Tot | D1713: BR4_Cluster1 | E1713: BPL131 | F1713: INT | G1713: %MW1326[18] | H1713: Water Transfer Pump 1 Flow Rate (m3/h) Flow Totals | K1713: BS1_Tags
A1714: BR4.UTILITIES.WATER.BS1.RWT.BPP1104 | B1714: BPP1104DRVSTAT | C1714: BPP1104DRVSTAT | D1714: BR4_Cluster1 | E1714: BPL131 | F1714: INT | G1714: %MW1381 | H1714: Water Transfer Pump 2 Status Word | K1714: BS1_Tags
... A1746: BR4.UTILITIES.WATER.BS1.BTY1502.FieldIO.FT03 | B1746: Tot | C1746: BTY1502FT03_Tot | D1746: BR4_Cluster1 | E1746: BPL131 | F1746: INT | G1746: %MW2658[18] | H1746: West Turkeys Nest Flow Rate (m3/h) Flow Totals | K1746: BS1_Tags
A1747: BR4.SRV.PWR.BSR131.BC02.BACS | B1747: Str1I | C1747: BSR131BC02BACSDAT1_Str1I | D1747: BR4_Cluster1 | E1747: BPL131 | F1747: INT | G1747: %MW4005 | H1747: BSR131BC02 Battery Charger BACS String 1 Current | I1747: 0 | J1747: 1000 | K1747: BS1_Tags
A1748: BR4.SRV.PWR.BSR131.BC02.BACS | B1748: Str1AltI | C1748: BSR131BC02BACSDAT1_Str1AltI | D1748: BR4_Cluster1 | E1748: BPL131 | F1748: INT | G1748: %MW4006 | H1748: BSR131BC02 Battery Charger BACS String 1 AC Current | I1748: 0 | J1748: 1000 | K1748: BS1_Tags
A1749: BR4.SRV.PWR.BSR131.BC02.BACS | B1749: Str1SumV | C1749: BSR131BC02BACSDAT1_Str1SumV | D1749: BR4_Cluster1 | E1749: BPL131 | F1749: INT | G1749: %MW4007 | H1749: BSR131BC02 Battery Charger BACS String 1 Overall Voltage | I1749: 0 | J1749: 1000 | K1749: BS1_Tags
A1750: BR4.SRV.PWR.BSR131.BC02.BACS | B1750: Str1AvgV | C1750: BSR131BC02BACSDAT1_Str1AvgV | D1750: BR4_Cluster1 | E1750: BPL131 | F1750: INT | G1750: %MW4008 | H1750: BSR131BC02 Battery Charger BACS String 1 Average Voltage | I1750: 0 | J1750: 1000 | K1750: BS1_Tags
A1751: BR4.SRV.PWR.BSR131.BC02.BACS | B1751: Mod1Tmp | C1751: BSR131BC02BACSDAT1_Mod1Tmp | D1751: BR4_Cluster1 | E1751: BPL131 | F1751: INT | G1751: %MW4009 | H1751: BSR131BC02 Battery Charger BACS Module 1 Temperature | I1751: 0 | J1751: 100 | K1751: BS1_Tags
A1752: BR4.SRV.PWR.BSR131.BC02.BACS | B1752: Mod1V | C1752: BSR131BC02BACSDAT1_Mod1V | D1752: BR4_Cluster1 | E1752: BPL131 | F1752: INT | G1752: %MW4010 | H1752: BSR131BC02 Battery Charger BACS Module 1 Voltage | I1752: 0 | J1752: 1000 | K1752: BS1_Tags
A1753: BR4.SRV.PWR.BSR131.BC02.BACS | B1753: Mod1Imp | C1753: BSR131BC02BACSDAT1_Mod1Imp | D1753: BR4_Cluster1 | E1753: BPL131 | F1753: INT | G1753: %MW4011 | H1753: BSR131BC02 Battery Charger BACS Module 1 Impedance | I1753: 0 | J1753: 1000 | K1753: BS1_Tags
A1754: BR4.SRV.PWR.BSR131.BC02.BACS | B1754: Mod1EqPerc | C1754: BSR131BC02BACSDAT1_Mod1EqPerc | D1754: BR4_Cluster1 | E1754: BPL131 | F1754: INT | G1754: %MW4013 | H1754: BSR131BC02 Battery Charger BACS Module 1 Equalizing / Balancing | I1754: 0 | J1754: 100 | K1754: BS1_Tags
A1755: BR4.SRV.PWR.BSR131.BC02.BACS | B1755: Mod2Tmp | C1755: BSR131BC02BACSDAT1_Mod2Tmp | D1755: BR4_Cluster1 | E1755: BPL131 | F1755: INT | G1755: %MW4014 | H1755: BSR131BC02 Battery Charger BACS Module 2 Temperature | I1755: 0 | J1755: 100 | K1755: BS1_Tags
A1756: BR4.SRV.PWR.BSR131.BC02.BACS | B1756: Mod2V | C1756: BSR131BC02BACSDAT1_Mod2V | D1756: BR4_Cluster1 | E1756: BPL131 | F1756: INT | G1756: %MW4015 | H1756: BSR131BC02 Battery Charger BACS Module 2 Voltage | I1756: 0 | J1756: 1000 | K1756: BS1_Tags
A1757: BR4.SRV.PWR.BSR131.BC02.BACS | B1757: Mod2Imp | C1757: BSR131BC02BACSDAT1_Mod2Imp | D1757: BR4_Cluster1 | E1757: BPL131 | F1757: INT | G1757: %MW4016 | H1757: BSR131BC02 Battery Charger BACS Module 2 Impedance | I1757: 0 | J1757: 1000 | K1757: BS1_Tags
A1758: BR4.SRV.PWR.BSR131.BC02.BACS | B1758: Mod2EqPerc | C1758: BSR131BC02BACSDAT1_Mod2EqPerc | D1758: BR4_Cluster1 | E1758: BPL131 | F1758: INT | G1758: %MW4018 | H1758: BSR131BC02 Battery Charger BACS Module 2 Equalizing / Balancing | I1758: 0 | J1758: 100 | K1758: BS1_Tags
... A1786: BR4.SRV.PWR.BSR131.BC02.BACS | B1786: Mod9EqPerc | C1786: BSR131BC02BACSDAT1_Mod9EqPerc | D1786: BR4_Cluster1 | E1786: BPL131 | F1786: INT | G1786: %MW4053 | H1786: BSR131BC02 Battery Charger BACS Module 9 Equalizing / Balancing | I1786: 0 | J1786: 100 | K1786: BS1_Tags
...

Sheet Alarms
A1: BR4.SRV.CTRLSYS.PLC.BPL131.Drop02 | B1: Ch01Flt_A | C1: BTY1502DX02DIO1PLM6_Ch01Flt_A | D1: BPL131 Drop 2 - BTY1502DX02 | E1: BR4_Cluster1 | F1: CAT_P3 | G1: AHI Module 6 Channel 1 Fault Alarm | I1: BPL131 | J1: BTY1502DX02 AHI Module 6 Channel 1 Fault Alarm | K1: BTY1502DX02DIO1PLM6_Ch01Flt_A | M1: BS1_Tags
A2: BR4.SRV.PWR.BSR131.BMC131.INC01 | B2: A | C2: BMC131INC01CB02_A | D2: =INDEX('Equipment Tree'!A:B,MATCH(A2,'Equipment Tree'!A:A,0),2) | E2: BR4_Cluster1 | G2: Process Bus Incomer Arc Flash Supply (Q204) Open | I2: BPL131 | J2: BMC131 Process Bus Incomer Arc Flash Supply (Q204) Open | K2: BMC131INC01CB02_A | M2: BS1_Tags
A3: BR4.SRV.PWR.BSR131.BMC131.INC01 | B3: A | C3: BMC131INC01CB03_A | D3: =INDEX('Equipment Tree'!A:B,MATCH(A3,'Equipment Tree'!A:A,0),2) | E3: BR4_Cluster1 | G3: Process Bus Incomer Incomer Circuit Breaker Spring Charge Supply (Q212) Open | I3: BPL131 | J3: BMC131 Process Bus Incomer Incomer Circuit Breaker Spring Charge Supply (Q212) Open | K3: BMC131INC01CB03_A | M3: BS1_Tags
A4: BR4.SRV.PWR.BSR131.BMC131.INC01 | B4: A | C4: BMC131INC01CB04_A | D4: =INDEX('Equipment Tree'!A:B,MATCH(A4,'Equipment Tree'!A:A,0),2) | E4: BR4_Cluster1 | G4: Process Bus Incomer Incomer Circuit Breaker Trip Supply (Q220) Open | I4: BPL131 | J4: BMC131 Process Bus Incomer Incomer Circuit Breaker Trip Supply (Q220) Open | K4: BMC131INC01CB04_A | M4: BS1_Tags
A5: BR4.SRV.PWR.BSR131.BMC131.INC01 | B5: A | C5: BMC131INC01CB05_A | D5: =INDEX('Equipment Tree'!A:B,MATCH(A5,'Equipment Tree'!A:A,0),2) | E5: BR4_Cluster1 | G5: Process Bus Incomer Incomer Circuit Breaker 24VDC Cubicle Bus Supply (Q256) Open | I5: BPL131 | J5: BMC131 Process Bus Incomer Incomer Circuit Breaker 24VDC Cubicle Bus Supply (Q256) Open | K5: BMC131INC01CB05_A | M5: BS1_Tags
A6: BR4.SRV.PWR.BSR131.BMC131.INC01 | B6: A | C6: BMC131INC01CB06_A | D6: =INDEX('Equipment Tree'!A:B,MATCH(A6,'Equipment Tree'!A:A,0),2) | E6: BR4_Cluster1 | G6: Process Bus Incomer 110VDC/24VDC Power Supply (Q215) Open | I6: BPL131 | J6: BMC131 Process Bus Incomer 110VDC/24VDC Power Supply (Q215) Open | K6: BMC131INC01CB06_A | M6: BS1_Tags
A7: BR4.SRV.PWR.BSR131.BMC131.INC01 | B7: CBCls_A | C7: BMC131INC01PR1_CBCls_A | D7: =INDEX('Equipment Tree'!A:B,MATCH(A7,'Equipment Tree'!A:A,0),2) | E7: BR4_Cluster1 | G7: Process Bus Incomer Protection Relay Circuit Breaker Alarm Alarm | I7: BPL131 | J7: BMC131 Process Bus Incomer Protection Relay Circuit Breaker Alarm Alarm | K7: BMC131INC01PR1_CBCls_A | M7: BS1_Tags
A8: BR4.SRV.PWR.BSR131.BMC131.INC01 | B8: CBFlt_A | C8: BMC131INC01PR1_CBFlt_A | D8: =INDEX('Equipment Tree'!A:B,MATCH(A8,'Equipment Tree'!A:A,0),2) | E8: BR4_Cluster1 | G8: Process Bus Incomer Protection Relay Fault Alarm | I8: BPL131 | J8: BMC131 Process Bus Incomer Protection Relay Fault Alarm | K8: BMC131INC01PR1_CBFlt_A | M8: BS1_Tags
A9: BR4.SRV.PWR.BSR131.BMC131.INC01 | B9: ComFlt_A | C9: BMC131INC01PR1_ComFlt_A | D9: =INDEX('Equipment Tree'!A:B,MATCH(A9,'Equipment Tree'!A:A,0),2) | E9: BR4_Cluster1 | G9: Process Bus Incomer Protection Relay Communications Fault Alarm Alarm | I9: BPL131 | J9: BMC131 Process Bus Incomer Protection Relay Communications Fault Alarm Alarm | K9: BMC131INC01PR1_ComFlt_A | M9: BS1_Tags
A10: BR4.SRV.PWR.BSR131.BMC131.INC01 | B10: Flt_A | C10: BMC131INC01PR1_Flt_A | D10: =INDEX('Equipment Tree'!A:B,MATCH(A10,'Equipment Tree'!A:A,0),2) | E10: BR4_Cluster1 | G10: Process Bus Incomer Protection Relay Fault Alarm Alarm | I10: BPL131 | J10: BMC131 Process Bus Incomer Protection Relay Fault Alarm Alarm | K10: BMC131INC01PR1_Flt_A | M10: BS1_Tags
A11: BR4.SRV.PWR.BSR131.BMC131.INC01 | B11: MntRqd_A | C11: BMC131INC01PR1_MntRqd_A | D11: =INDEX('Equipment Tree'!A:B,MATCH(A11,'Equipment Tree'!A:A,0),2) | E11: BR4_Cluster1 | G11: Process Bus Incomer Protection Relay Contactor Replacement Required Alarm Alarm | I11: BPL131 | J11: BMC131 Process Bus Incomer Protection Relay Contactor Replacement Required Alarm Alarm | K11: BMC131INC01PR1_MntRqd_A | M11: BS1_Tags
A12: BR4.SRV.PWR.BSR131.BMC131.INC01 | B12: A | C12: BMC131INC01TRP02_A | D12: =INDEX('Equipment Tree'!A:B,MATCH(A12,'Equipment Tree'!A:A,0),2) | E12: BR4_Cluster1 | G12: Process Bus Incomer Arc Flash Tripped | I12: BPL131 | J12: BMC131 Process Bus Incomer Arc Flash Tripped | K12: BMC131INC01TRP02_A | M12: BS1_Tags
A13: BR4.SRV.PWR.BSR131.BMC131.INC01 | B13: A | C13: BMC131INC01VDC01_A | D13: =INDEX('Equipment Tree'!A:B,MATCH(A13,'Equipment Tree'!A:A,0),2) | E13: BR4_Cluster1 | G13: Process Bus Incomer 24VDC Control Supply (Q267) Failure | I13: BPL131 | J13: BMC131 Process Bus Incomer 24VDC Control Supply (Q267) Failure | K13: BMC131INC01VDC01_A | M13: BS1_Tags
... A52: BR4.SRV.CTRLSYS.PLC.BPL131 | B52: Slot5_A | C52: BPL131PLM5_Flt_A | D52: =INDEX('Equipment Tree'!A:B,MATCH(A52,'Equipment Tree'!A:A,0),2) | E52: BR4_Cluster1 | G52: Ethernet Module Slot 5 Fault Alarm Alarm | I52: BPL131 | J52: NPI Hub PLC Ethernet Module Slot 5 Fault Alarm Alarm | K52: BPL131PLM5_Flt_A | M52: BS1_Tags
A53: =INDEX(Variables!A:C, MATCH(C53, Variables!C:C, 0), 1) | B53: 2_EqpAvlFlt_A | C53: BPP1101_2_EqpAvlFlt_A | D53: =INDEX('Equipment Tree'!A:B,MATCH(A53,'Equipment Tree'!A:A,0),2) | E53: BR4_Cluster1 | G53: No NPI and Process Water Pumps Available Fault Alarm | I53: BPL131 | J53: No NPI and Process Water Pumps Available Fault Alarm | K53: BPP1101_2_EqpAvlFlt_A | M53: BS1_Tags
A54: BR4.UTILITIES.WATER.BS1.RWD1.BPP1101.Sub.CB01 | B54: A | C54: BPP1101CB01_A | D54: =INDEX('Equipment Tree'!A:B,MATCH(A54,'Equipment Tree'!A:A,0),2) | E54: BR4_Cluster1 | G54: Production Plant and NPI Water Supply Pump 1 Main Circuit Breaker (Q103) Open | I54: BPL131 | J54: Production Plant and NPI Water Supply Pump 1 Main Circuit Breaker (Q103) Open | K54: BPP1101CB01_A | M54: BS1_Tags
A55: BR4.UTILITIES.WATER.BS1.RWD1.BPP1101 | B55: A | C55: BPP1101FS09_A | D55: =INDEX('Equipment Tree'!A:B,MATCH(A55,'Equipment Tree'!A:A,0),2) | E55: BR4_Cluster1 | G55: Pump Flow Switch Low Alarm | I55: BPL131 | J55: BPP1101FS09 Pump Flow Switch Low Alarm | K55: BPP1101FS09_A | M55: BS1_Tags
A56: BR4.UTILITIES.WATER.BS1.RWD1.BPP1101 | B56: FailStp_A | C56: BPP1101FS09_FailStp_A | D56: =INDEX('Equipment Tree'!A:B,MATCH(A56,'Equipment Tree'!A:A,0),2) | E56: BR4_Cluster1 | G56: Fail to Stop Alarm | I56: BPL131 | J56: BPP1101FS09 Fail to Stop Alarm | K56: BPP1101FS09_FailStp_A | M56: BS1_Tags
A57: BR4.UTILITIES.WATER.BS1.RWD1.BPP1101.FieldIO.FT03 | B57: Frz_A | C57: BPP1101FT03_Frz_A | D57: =INDEX('Equipment Tree'!A:B,MATCH(A57,'Equipment Tree'!A:A,0),2) | E57: BR4_Cluster1 | G57: Flow Transmitter Frozen Alarm | I57: BPL131 | J57: BPP1101FT03 Flow Transmitter Frozen Alarm | K57: BPP1101FT03_Frz_A | M57: BS1_Tags
A58: BR4.UTILITIES.WATER.BS1.RWD1.BPP1101.FieldIO.FT03 | B58: Hi_A | C58: BPP1101FT03_Hi_A | D58: =INDEX('Equipment Tree'!A:B,MATCH(A58,'Equipment Tree'!A:A,0),2) | E58: BR4_Cluster1 | G58: Pump Flow High Alarm | I58: BPL131 | J58: BPP1101FT03 Pump Flow High Alarm | K58: BPP1101FT03_Hi_A | M58: BS1_Tags
A59: BR4.UTILITIES.WATER.BS1.RWD1.BPP1101.FieldIO.FT03 | B59: HiHi_A | C59: BPP1101FT03_HiHi_A | D59: =INDEX('Equipment Tree'!A:B,MATCH(A59,'Equipment Tree'!A:A,0),2) | E59: BR4_Cluster1 | G59: NPI and Process Water Supply Flow High High Healthy | I59: BPL131 | J59: BPP1101FT03 NPI and Process Water Supply Flow High High Healthy | K59: BPP1101FT03_HiHi_A | M59: BS1_Tags
A60: BR4.UTILITIES.WATER.BS1.RWD1.BPP1101.FieldIO.FT03 | B60: Lo_A | C60: BPP1101FT03_Lo_A | D60: =INDEX('Equipment Tree'!A:B,MATCH(A60,'Equipment Tree'!A:A,0),2) | E60: BR4_Cluster1 | G60: Flow Low Alarm | I60: BPL131 | J60: BPP1101FT03 Flow Low Alarm | K60: BPP1101FT03_Lo_A | M60: BS1_Tags
A61: BR4.UTILITIES.WATER.BS1.RWD1.BPP1101.VS01 | B61: A | C61: BPP1101IS01_A | D61: =INDEX('Equipment Tree'!A:B,MATCH(A61,'Equipment Tree'!A:A,0),2) | E61: BR4_Cluster1 | G61: Isolator Open Alarm | I61: BPL131 | J61: BPP1101 Isolator Open Alarm | K61: BPP1101IS01_A | M61: BS1_Tags
A62: BR4.UTILITIES.WATER.BS1.RWD1.BPP1101.FieldIO.PT03 | B62: Frz_A | C62: BPP1101PT03_Frz_A | D62: =INDEX('Equipment Tree'!A:B,MATCH(A62,'Equipment Tree'!A:A,0),2) | E62: BR4_Cluster1 | G62: Pump Discharge Pressure Transmitter Frozen Alarm | I62: BPL131 | J62: BPP1101PT03 Pump Discharge Pressure Transmitter Frozen Alarm | K62: BPP1101PT03_Frz_A | M62: BS1_Tags
A63: BR4.UTILITIES.WATER.BS1.RWD1.BPP1101.FieldIO.PT03 | B63: HiHi_A | C63: BPP1101PT03_HiHi_A | D63: =INDEX('Equipment Tree'!A:B,MATCH(A63,'Equipment Tree'!A:A,0),2) | E63: BR4_Cluster1 | G63: System Pressure High High Alarm | I63: BPL131 | J63: BPP1101PT03 System Pressure High High Alarm | K63: BPP1101PT03_HiHi_A | M63: BS1_Tags
A64: BR4.UTILITIES.WATER.BS1.RWD1.BPP1101.FieldIO.PT03 | B64: LoLo_A | C64: BPP1101PT03_LoLo_A | D64: =INDEX('Equipment Tree'!A:B,MATCH(A64,'Equipment Tree'!A:A,0),2) | E64: BR4_Cluster1 | G64: Pump Discharge Pressure Low Low Alarm | I64: BPL131 | J64: BPP1101PT03 Pump Discharge Pressure Low Low Alarm | K64: BPP1101PT03_LoLo_A | M64: BS1_Tags
A65: BR4.UTILITIES.WATER.BS1.RWD1.BPP1101.FieldIO.PT10 | B65: Diff_A | C65: BPP1101PT10_Diff_A | D65: =INDEX('Equipment Tree'!A:B,MATCH(A65,'Equipment Tree'!A:A,0),2) | E65: BR4_Cluster1 | G65: NPI and Process Water Network Pressure Variance (PT10/PT11) Alarm | I65: BPL131 | J65: NPI and Process Water Network Pressure Variance (PT10/PT11) Alarm | K65: BPP1101PT10_Diff_A | M65: BS1_Tags
... A78: BR4.UTILITIES.WATER.BS1.RWD1.BPP1101.VS01 | B78: A | C78: BPP1101VS01VDC01_A | D78: =INDEX('Equipment Tree'!A:B,MATCH(A78,'Equipment Tree'!A:A,0),2) | E78: BR4_Cluster1 | G78: VVVF Drive BPP1101VS01 Control Supply (Q204) Failure | I78: BPL131 | J78: BPP1101VS01 VVVF Drive BPP1101VS01 Control Supply (Q204) Failure | K78: BPP1101VS01VDC01_A | M78: BS1_Tags
A79: =INDEX(Variables!A:C, MATCH(C79, Variables!C:C, 0), 1) | B79: A | C79: BPP1102CB01_A | D79: =INDEX('Equipment Tree'!A:B,MATCH(A79,'Equipment Tree'!A:A,0),2) | E79: BR4_Cluster1 | G79: Production Plant and NPI Water Supply Pump 2 Main Circuit Breaker (Q103) Open | I79: BPL131 | J79: Production Plant and NPI Water Supply Pump 2 Main Circuit Breaker (Q103) Open | K79: BPP1102CB01_A | M79: BS1_Tags
A80: =INDEX(Variables!A:C, MATCH(C80, Variables!C:C, 0), 1) | B80: A | C80: BPP1102FS10_A | D80: =INDEX('Equipment Tree'!A:B,MATCH(A80,'Equipment Tree'!A:A,0),2) | E80: BR4_Cluster1 | G80: Pump Flow Switch Low Alarm | I80: BPL131 | J80: BPP1102FS10 Pump Flow Switch Low Alarm | K80: BPP1102FS10_A | M80: BS1_Tags
A81: =INDEX(Variables!A:C, MATCH(C81, Variables!C:C, 0), 1) | B81: FailStp_A | C81: BPP1102FS10_FailStp_A | D81: =INDEX('Equipment Tree'!A:B,MATCH(A81,'Equipment Tree'!A:A,0),2) | E81: BR4_Cluster1 | G81: Pump Fail to Stop Alarm | I81: BPL131 | J81: BPP1102FS10 Pump Fail to Stop Alarm | K81: BPP1102FS10_FailStp_A | M81: BS1_Tags
A82: =INDEX(Variables!A:C, MATCH(C82, Variables!C:C, 0), 1) | B82: A | C82: BPP1102IS01_A | D82: =INDEX('Equipment Tree'!A:B,MATCH(A82,'Equipment Tree'!A:A,0),2) | E82: BR4_Cluster1 | G82: Isolator Open Alarm | I82: BPL131 | J82: BPP1102 Isolator Open Alarm | K82: BPP1102IS01_A | M82: BS1_Tags
A83: =INDEX(Variables!A:C, MATCH(C83, Variables!C:C, 0), 1) | B83: Frz_A | C83: BPP1102PT04_Frz_A | D83: =INDEX('Equipment Tree'!A:B,MATCH(A83,'Equipment Tree'!A:A,0),2) | E83: BR4_Cluster1 | G83: Pump Discharge Pressure Transmitter Frozen Alarm | I83: BPL131 | J83: BPP1102PT04 Pump Discharge Pressure Transmitter Frozen Alarm | K83: BPP1102PT04_Frz_A | M83: BS1_Tags
A84: =INDEX(Variables!A:C, MATCH(C84, Variables!C:C, 0), 1) | B84: HiHi_A | C84: BPP1102PT04_HiHi_A | D84: =INDEX('Equipment Tree'!A:B,MATCH(A84,'Equipment Tree'!A:A,0),2) | E84: BR4_Cluster1 | G84: Pump Discharge Pressure High High Alarm | I84: BPL131 | J84: BPP1102PT04 Pump Discharge Pressure High High Alarm | K84: BPP1102PT04_HiHi_A | M84: BS1_Tags
A85: =INDEX(Variables!A:C, MATCH(C85, Variables!C:C, 0), 1) | B85: LoLo_A | C85: BPP1102PT04_LoLo_A | D85: =INDEX('Equipment Tree'!A:B,MATCH(A85,'Equipment Tree'!A:A,0),2) | E85: BR4_Cluster1 | G85: Pump Discharge Pressure Low Low Alarm | I85: BPL131 | J85: BPP1102PT04 Pump Discharge Pressure Low Low Alarm | K85: BPP1102PT04_LoLo_A | M85: BS1_Tags
A86: =INDEX(Variables!A:C, MATCH(C86, Variables!C:C, 0), 1) | B86: A | C86: BPP1102THR01_A | D86: =INDEX('Equipment Tree'!A:B,MATCH(A86,'Equipment Tree'!A:A,0),2) | E86: BR4_Cluster1 | G86: Production Plant and NPI Water Supply Pump 2 Production Plant & NPI Water Supply Pump 2 (Standby) (K190) | I86: BPL131 | J86: Production Plant and NPI Water Supply Pump 2 Production Plant & NPI Water Supply Pump 2 (Standby) (K190) | K86: BPP1102THR01_A | M86: BS1_Tags
A87: =INDEX(Variables!A:C, MATCH(C87, Variables!C:C, 0), 1) | B87: A | C87: BPP1102TRP01_A | D87: =INDEX('Equipment Tree'!A:B,MATCH(A87,'Equipment Tree'!A:A,0),2) | E87: BR4_Cluster1 | G87: Main Circuit Breaker Tripped Alarm | I87: BPL131 | J87: BPP1102 Main Circuit Breaker Tripped Alarm | K87: BPP1102TRP01_A | M87: BS1_Tags
A88: =INDEX(Variables!A:C, MATCH(C88, Variables!C:C, 0), 1) | B88: A | C88: BPP1102VDC01_A | D88: =INDEX('Equipment Tree'!A:B,MATCH(A88,'Equipment Tree'!A:A,0),2) | E88: BR4_Cluster1 | G88: Production Plant and NPI Water Supply Pump 2 24VDC Control Supply (Q155) Failure | I88: BPL131 | J88: Production Plant and NPI Water Supply Pump 2 24VDC Control Supply (Q155) Failure | K88: BPP1102VDC01_A | M88: BS1_Tags
A89: =INDEX(Variables!A:C, MATCH(C89, Variables!C:C, 0), 1) | B89: ComFlt_A | C89: BPP1102VS01_ComFlt_A | D89: =INDEX('Equipment Tree'!A:B,MATCH(A89,'Equipment Tree'!A:A,0),2) | E89: BR4_Cluster1 | G89: BPP1107VS01 VSD Communications Fault Alarm | I89: BPL131 | J89: BPP1107VS01 VSD Communications Fault Alarm | K89: BPP1102VS01_ComFlt_A | M89: BS1_Tags
A90: =INDEX(Variables!A:C, MATCH(C90, Variables!C:C, 0), 1) | B90: Flt_A | C90: BPP1102VS01_Flt_A | D90: =INDEX('Equipment Tree'!A:B,MATCH(A90,'Equipment Tree'!A:A,0),2) | E90: BR4_Cluster1 | G90: VSD Fault Alarm | I90: BPL131 | J90: BPP1102VS01 VSD Fault Alarm | K90: BPP1102VS01_Flt_A | M90: BS1_Tags
...

Sheet Trends
A1: =INDEX(Variables!A:C, MATCH(C1, Variables!C:C, 0), 1) | B1: =INDEX(Variables!A:C, MATCH(C1, Variables!C:C, 0), 2) | C1: BMC131INC03PR1DAT1_FltSts1OK | D1: BR4_Cluster1 | E1: TRN_PERIODIC | G1: 5.787037e-05 | H1: =INDEX(Variables!A:H, MATCH(C1, Variables!C:C, 0), 8) | I1: 6 | J1: 1st | K1: 0 | L1: Floating Point (8-byte samples) | M1: BS1_Tags
A2: =INDEX(Variables!A:C, MATCH(C2, Variables!C:C, 0), 1) | B2: =INDEX(Variables!A:C, MATCH(C2, Variables!C:C, 0), 2) | C2: BMC131INC03PR1DAT1_FltSts1 | D2: BR4_Cluster1 | E2: TRN_PERIODIC | G2: 5.787037e-05 | H2: =INDEX(Variables!A:H, MATCH(C2, Variables!C:C, 0), 8) | I2: 6 | J2: 1st | K2: 0 | L2: Floating Point (8-byte samples) | M2: BS1_Tags
A3: =INDEX(Variables!A:C, MATCH(C3, Variables!C:C, 0), 1) | B3: =INDEX(Variables!A:C, MATCH(C3, Variables!C:C, 0), 2) | C3: BMC131INC03PR1DAT1_FltSts2OK | D3: BR4_Cluster1 | E3: TRN_PERIODIC | G3: 5.787037e-05 | H3: =INDEX(Variables!A:H, MATCH(C3, Variables!C:C, 0), 8) | I3: 6 | J3: 1st | K3: 0 | L3: Floating Point (8-byte samples) | M3: BS1_Tags
A4: =INDEX(Variables!A:C, MATCH(C4, Variables!C:C, 0), 1) | B4: =INDEX(Variables!A:C, MATCH(C4, Variables!C:C, 0), 2) | C4: BMC131INC03PR1DAT1_FltSts2 | D4: BR4_Cluster1 | E4: TRN_PERIODIC | G4: 5.787037e-05 | H4: =INDEX(Variables!A:H, MATCH(C4, Variables!C:C, 0), 8) | I4: 6 | J4: 1st | K4: 0 | L4: Floating Point (8-byte samples) | M4: BS1_Tags
A5: =INDEX(Variables!A:C, MATCH(C5, Variables!C:C, 0), 1) | B5: =INDEX(Variables!A:C, MATCH(C5, Variables!C:C, 0), 2) | C5: BMC131INC01PR1DAT1_FltSts1OK | D5: BR4_Cluster1 | E5: TRN_PERIODIC | G5: 5.787037e-05 | H5: =INDEX(Variables!A:H, MATCH(C5, Variables!C:C, 0), 8) | I5: 6 | J5: 1st | K5: 0 | L5: Floating Point (8-byte samples) | M5: BS1_Tags
A6: =INDEX(Variables!A:C, MATCH(C6, Variables!C:C, 0), 1) | B6: =INDEX(Variables!A:C, MATCH(C6, Variables!C:C, 0), 2) | C6: BMC131INC01PR1DAT1_FltSts1 | D6: BR4_Cluster1 | E6: TRN_PERIODIC | G6: 5.787037e-05 | H6: =INDEX(Variables!A:H, MATCH(C6, Variables!C:C, 0), 8) | I6: 6 | J6: 1st | K6: 0 | L6: Floating Point (8-byte samples) | M6: BS1_Tags
A7: =INDEX(Variables!A:C, MATCH(C7, Variables!C:C, 0), 1) | B7: =INDEX(Variables!A:C, MATCH(C7, Variables!C:C, 0), 2) | C7: BMC131INC01PR1DAT1_FltSts2OK | D7: BR4_Cluster1 | E7: TRN_PERIODIC | G7: 5.787037e-05 | H7: =INDEX(Variables!A:H, MATCH(C7, Variables!C:C, 0), 8) | I7: 6 | J7: 1st | K7: 0 | L7: Floating Point (8-byte samples) | M7: BS1_Tags
A8: =INDEX(Variables!A:C, MATCH(C8, Variables!C:C, 0), 1) | B8: =INDEX(Variables!A:C, MATCH(C8, Variables!C:C, 0), 2) | C8: BMC131INC01PR1DAT1_FltSts2 | D8: BR4_Cluster1 | E8: TRN_PERIODIC | G8: 5.787037e-05 | H8: =INDEX(Variables!A:H, MATCH(C8, Variables!C:C, 0), 8) | I8: 6 | J8: 1st | K8: 0 | L8: Floating Point (8-byte samples) | M8: BS1_Tags
A9: =INDEX(Variables!A:C, MATCH(C9, Variables!C:C, 0), 1) | B9: =INDEX(Variables!A:C, MATCH(C9, Variables!C:C, 0), 2) | C9: BMC131INC02PR1DAT1_FltSts1OK | D9: BR4_Cluster1 | E9: TRN_PERIODIC | G9: 5.787037e-05 | H9: =INDEX(Variables!A:H, MATCH(C9, Variables!C:C, 0), 8) | I9: 6 | J9: 1st | K9: 0 | L9: Floating Point (8-byte samples) | M9: BS1_Tags
A10: =INDEX(Variables!A:C, MATCH(C10, Variables!C:C, 0), 1) | B10: =INDEX(Variables!A:C, MATCH(C10, Variables!C:C, 0), 2) | C10: BMC131INC02PR1DAT1_FltSts1 | D10: BR4_Cluster1 | E10: TRN_PERIODIC | G10: 5.787037e-05 | H10: =INDEX(Variables!A:H, MATCH(C10, Variables!C:C, 0), 8) | I10: 6 | J10: 1st | K10: 0 | L10: Floating Point (8-byte samples) | M10: BS1_Tags
A11: =INDEX(Variables!A:C, MATCH(C11, Variables!C:C, 0), 1) | B11: =INDEX(Variables!A:C, MATCH(C11, Variables!C:C, 0), 2) | C11: BMC131INC02PR1DAT1_FltSts2OK | D11: BR4_Cluster1 | E11: TRN_PERIODIC | G11: 5.787037e-05 | H11: =INDEX(Variables!A:H, MATCH(C11, Variables!C:C, 0), 8) | I11: 6 | J11: 1st | K11: 0 | L11: Floating Point (8-byte samples) | M11: BS1_Tags
A12: =INDEX(Variables!A:C, MATCH(C12, Variables!C:C, 0), 1) | B12: =INDEX(Variables!A:C, MATCH(C12, Variables!C:C, 0), 2) | C12: BMC131INC02PR1DAT1_FltSts2 | D12: BR4_Cluster1 | E12: TRN_PERIODIC | G12: 5.787037e-05 | H12: =INDEX(Variables!A:H, MATCH(C12, Variables!C:C, 0), 8) | I12: 6 | J12: 1st | K12: 0 | L12: Floating Point (8-byte samples) | M12: BS1_Tags
... A593: =INDEX(Variables!A:C, MATCH(C593, Variables!C:C, 0), 1) | B593: =INDEX(Variables!A:C, MATCH(C593, Variables!C:C, 0), 2) | C593: BSR131BC02CordexDAT1_MaxRecAmbTmp | D593: BR4_Cluster1 | E593: TRN_PERIODIC | G593: 5.787037e-05 | H593: =INDEX(Variables!A:H, MATCH(C593, Variables!C:C, 0), 8) | I593: 6 | J593: 1st | K593: 0 | L593: Floating Point (8-byte samples) | M593: BS1_Tags
A594: =INDEX(Variables!A:C, MATCH(C594, Variables!C:C, 0), 1) | B594: Iavg | C594: BPP1101VS01DAT1_Iavg | D594: BR4_Cluster1 | E594: TRN_PERIODIC | G594: 5.787037e-05 | H594: =INDEX(Variables!A:H, MATCH(C594, Variables!C:C, 0), 8) | I594: 6 | J594: 1st | K594: 0 | L594: Floating Point (8-byte samples) | M594: BS1_Tags
A595: =INDEX(Variables!A:C, MATCH(C595, Variables!C:C, 0), 1) | B595: Spd | C595: BPP1101VS01DAT1_Spd | D595: BR4_Cluster1 | E595: TRN_PERIODIC | G595: 5.787037e-05 | H595: =INDEX(Variables!A:H, MATCH(C595, Variables!C:C, 0), 8) | I595: 6 | J595: 1st | K595: 0 | L595: Floating Point (8-byte samples) | M595: BS1_Tags
A596: =INDEX(Variables!A:C, MATCH(C596, Variables!C:C, 0), 1) | B596: Trq | C596: BPP1101VS01DAT1_Trq | D596: BR4_Cluster1 | E596: TRN_PERIODIC | G596: 5.787037e-05 | H596: =INDEX(Variables!A:H, MATCH(C596, Variables!C:C, 0), 8) | I596: 6 | J596: 1st | K596: 0 | L596: Floating Point (8-byte samples) | M596: BS1_Tags
A597: =INDEX(Variables!A:C, MATCH(C597, Variables!C:C, 0), 1) | B597: Frq | C597: BPP1101VS01DAT1_Frq | D597: BR4_Cluster1 | E597: TRN_PERIODIC | G597: 5.787037e-05 | H597: =INDEX(Variables!A:H, MATCH(C597, Variables!C:C, 0), 8) | I597: 6 | J597: 1st | K597: 0 | L597: Floating Point (8-byte samples) | M597: BS1_Tags
A598: =INDEX(Variables!A:C, MATCH(C598, Variables!C:C, 0), 1) | B598: Pwr | C598: BPP1101VS01DAT1_Pwr | D598: BR4_Cluster1 | E598: TRN_PERIODIC | G598: 5.787037e-05 | H598: =INDEX(Variables!A:H, MATCH(C598, Variables!C:C, 0), 8) | I598: 6 | J598: 1st | K598: 0 | L598: Floating Point (8-byte samples) | M598: BS1_Tags
A599: =INDEX(Variables!A:C, MATCH(C599, Variables!C:C, 0), 1) | B599: Tmp | C599: BPP1101VS01DAT1_Tmp | D599: BR4_Cluster1 | E599: TRN_PERIODIC | G599: 5.787037e-05 | H599: =INDEX(Variables!A:H, MATCH(C599, Variables!C:C, 0), 8) | I599: 6 | J599: 1st | K599: 0 | L599: Floating Point (8-byte samples) | M599: BS1_Tags
A600: =INDEX(Variables!A:C, MATCH(C600, Variables!C:C, 0), 1) | B600: SpdEng | C600: BPP1101VS01DAT1_SpdEng | D600: BR4_Cluster1 | E600: TRN_PERIODIC | G600: 5.787037e-05 | H600: =INDEX(Variables!A:H, MATCH(C600, Variables!C:C, 0), 8) | I600: 6 | J600: 1st | K600: 0 | L600: Floating Point (8-byte samples) | M600: BS1_Tags
A601: =INDEX(Variables!A:C, MATCH(C601, Variables!C:C, 0), 1) | B601: Iavg | C601: BPP1102VS01DAT1_Iavg | D601: BR4_Cluster1 | E601: TRN_PERIODIC | G601: 5.787037e-05 | H601: =INDEX(Variables!A:H, MATCH(C601, Variables!C:C, 0), 8) | I601: 6 | J601: 1st | K601: 0 | L601: Floating Point (8-byte samples) | M601: BS1_Tags
A602: =INDEX(Variables!A:C, MATCH(C602, Variables!C:C, 0), 1) | B602: Spd | C602: BPP1102VS01DAT1_Spd | D602: BR4_Cluster1 | E602: TRN_PERIODIC | G602: 5.787037e-05 | H602: =INDEX(Variables!A:H, MATCH(C602, Variables!C:C, 0), 8) | I602: 6 | J602: 1st | K602: 0 | L602: Floating Point (8-byte samples) | M602: BS1_Tags
A603: =INDEX(Variables!A:C, MATCH(C603, Variables!C:C, 0), 1) | B603: Trq | C603: BPP1102VS01DAT1_Trq | D603: BR4_Cluster1 | E603: TRN_PERIODIC | G603: 5.787037e-05 | H603: =INDEX(Variables!A:H, MATCH(C603, Variables!C:C, 0), 8) | I603: 6 | J603: 1st | K603: 0 | L603: Floating Point (8-byte samples) | M603: BS1_Tags
A604: =INDEX(Variables!A:C, MATCH(C604, Variables!C:C, 0), 1) | B604: Frq | C604: BPP1102VS01DAT1_Frq | D604: BR4_Cluster1 | E604: TRN_PERIODIC | G604: 5.787037e-05 | H604: =INDEX(Variables!A:H, MATCH(C604, Variables!C:C, 0), 8) | I604: 6 | J604: 1st | K604: 0 | L604: Floating Point (8-byte samples) | M604: BS1_Tags
A605: =INDEX(Variables!A:C, MATCH(C605, Variables!C:C, 0), 1) | B605: Pwr | C605: BPP1102VS01DAT1_Pwr | D605: BR4_Cluster1 | E605: TRN_PERIODIC | G605: 5.787037e-05 | H605: =INDEX(Variables!A:H, MATCH(C605, Variables!C:C, 0), 8) | I605: 6 | J605: 1st | K605: 0 | L605: Floating Point (8-byte samples) | M605: BS1_Tags
... A642: =INDEX(Variables!A:C, MATCH(C642, Variables!C:C, 0), 1) | B642: SpdEng | C642: BPP1107VS01DAT1_SpdEng | D642: BR4_Cluster1 | E642: TRN_PERIODIC | G642: 5.787037e-05 | H642: =INDEX(Variables!A:H, MATCH(C642, Variables!C:C, 0), 8) | I642: 6 | J642: 1st | K642: 0 | L642: Floating Point (8-byte samples) | M642: BS1_Tags
A643: =INDEX(Variables!A:C, MATCH(C643, Variables!C:C, 0), 1) | C643: BPP1101PIC01_KD | D643: BR4_Cluster1 | E643: TRN_PERIODIC | G643: 5.787037e-05 | H643: =INDEX(Variables!A:H, MATCH(C643, Variables!C:C, 0), 8) | I643: 6 | J643: 1st | K643: 0 | L643: Floating Point (8-byte samples) | M643: BS1_Tags
A644: =INDEX(Variables!A:C, MATCH(C644, Variables!C:C, 0), 1) | C644: BPP1101PIC01_KI | D644: BR4_Cluster1 | E644: TRN_PERIODIC | G644: 5.787037e-05 | H644: =INDEX(Variables!A:H, MATCH(C644, Variables!C:C, 0), 8) | I644: 6 | J644: 1st | K644: 0 | L644: Floating Point (8-byte samples) | M644: BS1_Tags
A645: =INDEX(Variables!A:C, MATCH(C645, Variables!C:C, 0), 1) | C645: BPP1101PIC01_KP | D645: BR4_Cluster1 | E645: TRN_PERIODIC | G645: 5.787037e-05 | H645: =INDEX(Variables!A:H, MATCH(C645, Variables!C:C, 0), 8) | I645: 6 | J645: 1st | K645: 0 | L645: Floating Point (8-byte samples) | M645: BS1_Tags
A646: =INDEX(Variables!A:C, MATCH(C646, Variables!C:C, 0), 1) | C646: BPP1101PIC01_OP | D646: BR4_Cluster1 | E646: TRN_PERIODIC | G646: 5.787037e-05 | H646: =INDEX(Variables!A:H, MATCH(C646, Variables!C:C, 0), 8) | I646: 6 | J646: 1st | K646: 0 | L646: Floating Point (8-byte samples) | M646: BS1_Tags
A647: =INDEX(Variables!A:C, MATCH(C647, Variables!C:C, 0), 1) | C647: BPP1101PIC01_OPMan | D647: BR4_Cluster1 | E647: TRN_PERIODIC | G647: 5.787037e-05 | H647: =INDEX(Variables!A:H, MATCH(C647, Variables!C:C, 0), 8) | I647: 6 | J647: 1st | K647: 0 | L647: Floating Point (8-byte samples) | M647: BS1_Tags
A648: =INDEX(Variables!A:C, MATCH(C648, Variables!C:C, 0), 1) | C648: BPP1103LIC01_KD | D648: BR4_Cluster1 | E648: TRN_PERIODIC | G648: 5.787037e-05 | H648: =INDEX(Variables!A:H, MATCH(C648, Variables!C:C, 0), 8) | I648: 6 | J648: 1st | K648: 0 | L648: Floating Point (8-byte samples) | M648: BS1_Tags
A649: =INDEX(Variables!A:C, MATCH(C649, Variables!C:C, 0), 1) | C649: BPP1103LIC01_KI | D649: BR4_Cluster1 | E649: TRN_PERIODIC | G649: 5.787037e-05 | H649: =INDEX(Variables!A:H, MATCH(C649, Variables!C:C, 0), 8) | I649: 6 | J649: 1st | K649: 0 | L649: Floating Point (8-byte samples) | M649: BS1_Tags
A650: =INDEX(Variables!A:C, MATCH(C650, Variables!C:C, 0), 1) | C650: BPP1103LIC01_KP | D650: BR4_Cluster1 | E650: TRN_PERIODIC | G650: 5.787037e-05 | H650: =INDEX(Variables!A:H, MATCH(C650, Variables!C:C, 0), 8) | I650: 6 | J650: 1st | K650: 0 | L650: Floating Point (8-byte samples) | M650: BS1_Tags
A651: =INDEX(Variables!A:C, MATCH(C651, Variables!C:C, 0), 1) | C651: BPP1103LIC01_OP | D651: BR4_Cluster1 | E651: TRN_PERIODIC | G651: 5.787037e-05 | H651: =INDEX(Variables!A:H, MATCH(C651, Variables!C:C, 0), 8) | I651: 6 | J651: 1st | K651: 0 | L651: Floating Point (8-byte samples) | M651: BS1_Tags
A652: =INDEX(Variables!A:C, MATCH(C652, Variables!C:C, 0), 1) | C652: BPP1103LIC01_OPMan | D652: BR4_Cluster1 | E652: TRN_PERIODIC | G652: 5.787037e-05 | H652: =INDEX(Variables!A:H, MATCH(C652, Variables!C:C, 0), 8) | I652: 6 | J652: 1st | K652: 0 | L652: Floating Point (8-byte samples) | M652: BS1_Tags
A653: =INDEX(Variables!A:C, MATCH(C653, Variables!C:C, 0), 1) | C653: BSTD1106FIC01_KD | D653: BR4_Cluster1 | E653: TRN_PERIODIC | G653: 5.787037e-05 | H653: =INDEX(Variables!A:H, MATCH(C653, Variables!C:C, 0), 8) | I653: 6 | J653: 1st | K653: 0 | L653: Floating Point (8-byte samples) | M653: BS1_Tags
A654: =INDEX(Variables!A:C, MATCH(C654, Variables!C:C, 0), 1) | C654: BSTD1106FIC01_KI | D654: BR4_Cluster1 | E654: TRN_PERIODIC | G654: 5.787037e-05 | H654: =INDEX(Variables!A:H, MATCH(C654, Variables!C:C, 0), 8) | I654: 6 | J654: 1st | K654: 0 | L654: Floating Point (8-byte samples) | M654: BS1_Tags
... A662: =INDEX(Variables!A:C, MATCH(C662, Variables!C:C, 0), 1) | C662: BSTD1107FIC01_OPMan | D662: BR4_Cluster1 | E662: TRN_PERIODIC | G662: 5.787037e-05 | H662: =INDEX(Variables!A:H, MATCH(C662, Variables!C:C, 0), 8) | I662: 6 | J662: 1st | K662: 0 | L662: Floating Point (8-byte samples) | M662: BS1_Tags
A663: =INDEX(Variables!A:C, MATCH(C663, Variables!C:C, 0), 1) | B663: =INDEX(Variables!A:C, MATCH(C663, Variables!C:C, 0), 2) | C663: BSR131BC02BACSDAT1_AlmID1 | D663: BR4_Cluster1 | E663: TRN_PERIODIC | G663: 5.787037e-05 | H663: =INDEX(Variables!A:H, MATCH(C663, Variables!C:C, 0), 8) | I663: 6 | J663: 1st | K663: 0 | L663: Floating Point (8-byte samples) | M663: BS1_Tags
...

Sheet Runtime Parameters

Sheet References

Sheet REF Variables

Sheet REF Alarms
A1: BR4_Tags | B1: R1Col_W | C1: ACS/SMS PLC505 M580 | D1: BRC501 Collision Alarm | E1: R1Col_W | G1: CAT_P2 | I1: PRIV_ALARMACK | J1: A_CM_ACSSMS | K1: BRC501 Collision Alarm | M1: R1Col_W | R1: C_HIPRI | S1: ACSNEW | T1: Class_Equipment | U1: BR4_Cluster1 | X1: BR4.STOCKYARD.ACS.BRC501
A2: BR4_Tags | B2: S2Col_W | C2: ACS/SMS PLC505 M580 | D2: BST502 Collision Alarm | E2: S2Col_W | G2: CAT_P2 | I2: PRIV_ALARMACK | J2: A_CM_ACSSMS | K2: BST502 Collision Alarm | M2: S2Col_W | R2: C_HIPRI | S2: ACSNEW | T2: Class_Equipment | U2: BR4_Cluster1 | X2: BR4.STOCKYARD.ACS.BST502
A3: BR4_Tags | B3: S1Col_W | C3: ACS/SMS PLC505 M580 | D3: BST501 Collision Alarm | E3: S1Col_W | G3: CAT_P2 | I3: PRIV_ALARMACK | J3: A_CM_ACSSMS | K3: BST501 Collision Alarm | M3: S1Col_W | R3: C_HIPRI | S3: ACSNEW | T3: Class_Equipment | U3: BR4_Cluster1 | X3: BR4.STOCKYARD.ACS.BST501
A4: BR4_Tags | B4: R1ACSByp_A | C4: ACS/SMS PLC505 M580 | D4: BRC501 Anti-Col Bypassed Alarm | E4: R1ACSByp_A | G4: CAT_P2 | I4: PRIV_ALARMACK | J4: A_CM_ACSSMS | K4: BRC501 Anti-Col Bypassed Alarm | M4: R1ACSByp_A | R4: C_HIPRI | S4: ACSNEW | T4: Class_Equipment | U4: BR4_Cluster1 | X4: BR4.STOCKYARD.ACS.BRC501
A5: BR4_Tags | B5: S2ACSByp_A | C5: ACS/SMS PLC505 M580 | D5: BST502 Anti-Col Bypassed Alarm | E5: S2ACSByp_A | G5: CAT_P2 | I5: PRIV_ALARMACK | J5: A_CM_ACSSMS | K5: BST502 Anti-Col Bypassed Alarm | M5: S2ACSByp_A | R5: C_HIPRI | S5: ACSNEW | T5: Class_Equipment | U5: BR4_Cluster1 | X5: BR4.STOCKYARD.ACS.BST502
A6: BR4_Tags | B6: S1ACSByp_A | C6: ACS/SMS PLC505 M580 | D6: BST501 Anti-Col Bypassed Alarm | E6: S1ACSByp_A | G6: CAT_P2 | I6: PRIV_ALARMACK | J6: A_CM_ACSSMS | K6: BST501 Anti-Col Bypassed Alarm | M6: S1ACSByp_A | R6: C_HIPRI | S6: ACSNEW | T6: Class_Equipment | U6: BR4_Cluster1 | X6: BR4.STOCKYARD.ACS.BST501
A7: BR4_Tags | B7: R1LastPos_A | C7: ACS/SMS PLC505 M580 | D7: BRC501 Anti-Col In Last Known Position Alarm | E7: R1LastPos_A | G7: CAT_P3 | I7: PRIV_ALARMACK | J7: A_CM_ACSSMS | K7: BRC501 Anti-Col In Last Known Position Alarm | M7: R1LastPos_A | R7: C_LOPRI | S7: ACSNEW | T7: Class_Equipment | U7: BR4_Cluster1 | X7: BR4.STOCKYARD.ACS.BRC501
A8: BR4_Tags | B8: S2LastPos_A | C8: ACS/SMS PLC505 M580 | D8: BST502 Anti-Col In Last Known Position Alarm | E8: S2LastPos_A | G8: CAT_P3 | I8: PRIV_ALARMACK | J8: A_CM_ACSSMS | K8: BST502 Anti-Col In Last Known Position Alarm | M8: S2LastPos_A | R8: C_LOPRI | S8: ACSNEW | T8: Class_Equipment | U8: BR4_Cluster1 | X8: BR4.STOCKYARD.ACS.BST502
A9: BR4_Tags | B9: S1LastPos_A | C9: ACS/SMS PLC505 M580 | D9: BST501 Anti-Col In Last Known Position Alarm | E9: S1LastPos_A | G9: CAT_P3 | I9: PRIV_ALARMACK | J9: A_CM_ACSSMS | K9: BST501 Anti-Col In Last Known Position Alarm | M9: S1LastPos_A | R9: C_LOPRI | S9: ACSNEW | T9: Class_Equipment | U9: BR4_Cluster1 | X9: BR4.STOCKYARD.ACS.BST501
A10: BR4_Tags | B10: R1Col_A | C10: ACS/SMS PLC505 M580 | D10: BRC501 Crash Alarm | E10: R1Col_A | G10: CAT_P1 | I10: PRIV_ALARMACK | J10: A_CM_ACSSMS | K10: BRC501 Crash Alarm | M10: R1Col_A | R10: C_CRITPRI | S10: ACSNEW | T10: Class_Equipment | U10: BR4_Cluster1 | X10: BR4.STOCKYARD.ACS.BRC501
A11: BR4_Tags | B11: S2Col_A | C11: ACS/SMS PLC505 M580 | D11: BST502 Crash Alarm | E11: S2Col_A | G11: CAT_P1 | I11: PRIV_ALARMACK | J11: A_CM_ACSSMS | K11: BST502 Crash Alarm | M11: S2Col_A | R11: C_CRITPRI | S11: ACSNEW | T11: Class_Equipment | U11: BR4_Cluster1 | X11: BR4.STOCKYARD.ACS.BST502
A12: BR4_Tags | B12: S1Col_A | C12: ACS/SMS PLC505 M580 | D12: BST501 Crash Alarm | E12: S1Col_A | G12: CAT_P1 | I12: PRIV_ALARMACK | J12: A_CM_ACSSMS | K12: BST501 Crash Alarm | M12: S1Col_A | R12: C_CRITPRI | S12: ACSNEW | T12: Class_Equipment | U12: BR4_Cluster1 | X12: BR4.STOCKYARD.ACS.BST501
... A16: BR4_Tags | B16: BPL505_CPUBattFlt_A | C16: ACS/SMS PLC505 M580 | D16: BPL505 PLC Battery Fault Alarm | E16: BPL505_CPUBattFlt_A | G16: CAT_P2 | I16: PRIV_ALARMACK | J16: A_CM_ACSSMS | K16: BPL505 PLC Battery Fault Alarm | M16: BPL505_CPUBattFlt_A | R16: C_HIPRI | S16: ACSNEW | T16: Class_Equipment | U16: BR4_Cluster1 | X16: BR4.SRV.CTRLSYS.PLC.BPL505
A17: BR4_Tags | B17: BPL505_CPUEthLinkOK_A | C17: ACS/SMS PLC505 M580 | D17: BPL505 PLC CPU Ethernet Link OK | E17: BPL505_CPUEthLinkOK_A | G17: CAT_P2 | I17: PRIV_ALARMACK | J17: A_CM_ACSSMS | K17: BPL505 PLC CPU Ethernet Link OK | M17: BPL505_CPUEthLinkOK_A | R17: C_HIPRI | S17: ACSNEW | T17: Class_Equipment | U17: BR4_Cluster1 | X17: BR4.SRV.CTRLSYS.PLC.BPL505 | Y17: Slot1_A
A18: BR4_Tags | B18: BPL505_CPUEthSysOK_A | C18: ACS/SMS PLC505 M580 | D18: BPL505 PLC CPU Ethernet OK | E18: BPL505_CPUEthSysOK_A | G18: CAT_P2 | I18: PRIV_ALARMACK | J18: A_CM_ACSSMS | K18: BPL505 PLC CPU Ethernet OK | M18: BPL505_CPUEthSysOK_A | R18: C_HIPRI | S18: ACSNEW | T18: Class_Equipment | U18: BR4_Cluster1 | X18: BR4.SRV.CTRLSYS.PLC.BPL505
A19: BR4_Tags | B19: BPL505_NOC1SysOK_A | C19: ACS/SMS PLC505 M580 | D19: BPL505 PLC NOC1 Ethernet OK | E19: BPL505_NOC1SysOK_A | G19: CAT_P2 | I19: PRIV_ALARMACK | J19: A_CM_ACSSMS | K19: BPL505 PLC NOC1 Ethernet OK | M19: BPL505_NOC1SysOK_A | R19: C_HIPRI | S19: ACSNEW | T19: Class_Equipment | U19: BR4_Cluster1 | X19: BR4.SRV.CTRLSYS.PLC.BPL505
A20: BR4_Tags | B20: BPL505_NOC1LinkOK_A | C20: ACS/SMS PLC505 M580 | D20: BPL505 PLC NOC1 Ethernet Link OK | E20: BPL505_NOC1LinkOK_A | G20: CAT_P2 | I20: PRIV_ALARMACK | J20: A_CM_ACSSMS | K20: BPL505 PLC NOC1 Ethernet Link OK | M20: BPL505_NOC1LinkOK_A | R20: C_HIPRI | S20: ACSNEW | T20: Class_Equipment | U20: BR4_Cluster1 | X20: BR4.SRV.CTRLSYS.PLC.BPL505 | Y20: Slot2_A
A21: BR4_Tags | B21: BPL505_NOC2SysOK_A | C21: ACS/SMS PLC505 M580 | D21: BPL505 PLC NOC2 Ethernet OK | E21: BPL505_NOC2SysOK_A | G21: CAT_P2 | I21: PRIV_ALARMACK | J21: A_CM_ACSSMS | K21: BPL505 PLC NOC2 Ethernet OK | M21: BPL505_NOC2SysOK_A | R21: C_HIPRI | S21: ACSNEW | T21: Class_Equipment | U21: BR4_Cluster1 | X21: BR4.SRV.CTRLSYS.PLC.BPL505
A22: BR4_Tags | B22: BPL505_NOC2LinkOK_A | C22: ACS/SMS PLC505 M580 | D22: BPL505 PLC NOC2 Ethernet Link OK | E22: BPL505_NOC2LinkOK_A | G22: CAT_P2 | I22: PRIV_ALARMACK | J22: A_CM_ACSSMS | K22: BPL505 PLC NOC2 Ethernet Link OK | M22: BPL505_NOC2LinkOK_A | R22: C_HIPRI | S22: ACSNEW | T22: Class_Equipment | U22: BR4_Cluster1 | X22: BR4.SRV.CTRLSYS.PLC.BPL505 | Y22: Slot3_A
A23: BR4_Tags | B23: B201_CommsFlt_A | C23: Bore | D23: Comms Fail | E23: B201_CommsFlt_A | G23: CAT_P3 | I23: PRIV_ALARMACK | J23: A_P1_SERV | M23: B201_CommsFlt_A | R23: C_LOPRI | S23: B201 | T23: Class_Equipment | U23: BR4_Cluster1 | X23: BR4.UTILITIES.WATER.WBBWD.B201
A24: BR4_Tags | B24: B201_DCOK01_A | C24: Bore | D24: 24V I/O Supply Fault | E24: B201_DCOK01_A | G24: CAT_P3 | I24: PRIV_ALARMACK | J24: A_P1_SERV | M24: B201_DCOK01_A | R24: C_LOPRI | S24: B201 | T24: Class_Process | U24: BR4_Cluster1 | X24: BR4.UTILITIES.WATER.WBBWD.B201
A25: BR4_Tags | B25: B201_DCOK02_A | C25: Bore | D25: 24V Supply Fault | E25: B201_DCOK02_A | G25: CAT_P3 | I25: PRIV_ALARMACK | J25: A_P1_SERV | M25: B201_DCOK02_A | R25: C_LOPRI | S25: B201 | T25: Class_Process | U25: BR4_Cluster1 | X25: BR4.UTILITIES.WATER.WBBWD.B201
A26: BR4_Tags | B26: B201_EARTH_A | C26: Bore | D26: Earth Leakage Fault | E26: B201_EARTH_A | G26: CAT_P3 | I26: PRIV_ALARMACK | J26: A_P1_SERV | M26: B201_EARTH_A | R26: C_LOPRI | S26: B201 | T26: Class_Process | U26: BR4_Cluster1 | X26: BR4.UTILITIES.WATER.WBBWD.B201
A27: BR4_Tags | B27: B201_ECR_A | C27: Bore | D27: ECR Fault | E27: B201_ECR_A | G27: CAT_P3 | I27: PRIV_ALARMACK | J27: A_P1_SERV | M27: B201_ECR_A | R27: C_LOPRI | S27: B201 | T27: Class_Process | U27: BR4_Cluster1 | X27: BR4.UTILITIES.WATER.WBBWD.B201
A28: BR4_Tags | B28: B201_FS01_A | C28: Bore | D28: Flow Switch Low | E28: B201_FS01_A | G28: CAT_P3 | I28: PRIV_ALARMACK | J28: A_P1_SERV | M28: B201_FS01_A | R28: C_LOPRI | S28: B201 | T28: Class_Process | U28: BR4_Cluster1 | X28: BR4.UTILITIES.WATER.WBBWD.B201
A29: BR4_Tags | B29: B201_FT01_Lo_A | C29: Bore | D29: Flow Low | E29: B201_FT01_Lo_A | G29: CAT_P3 | I29: PRIV_ALARMACK | J29: A_P1_SERV | M29: B201_FT01_Lo_A | R29: C_LOPRI | S29: B201 | T29: Class_Process | U29: BR4_Cluster1 | X29: BR4.UTILITIES.WATER.WBBWD.B201.FT01
A30: BR4_Tags | B30: B201_GenFlt_A | C30: Bore | D30: Generator Alarm | E30: B201_GenFlt_A | G30: CAT_P3 | I30: PRIV_ALARMACK | J30: A_P1_SERV | M30: B201_GenFlt_A | R30: C_LOPRI | S30: B201 | T30: Class_Process | U30: BR4_Cluster1 | X30: BR4.UTILITIES.WATER.WBBWD.B201
A31: BR4_Tags | B31: B201_GenFuelLow_A | C31: Bore | D31: Generator Fuel Low | E31: B201_GenFuelLow_A | G31: CAT_P3 | I31: PRIV_ALARMACK | J31: A_P1_SERV | M31: B201_GenFuelLow_A | R31: C_LOPRI | S31: B201 | T31: Class_Process | U31: BR4_Cluster1 | X31: BR4.UTILITIES.WATER.WBBWD.B201
A32: BR4_Tags | B32: B201_GenSttFail_A | C32: Bore | D32: Generator Failed to Start | E32: B201_GenSttFail_A | G32: CAT_P3 | I32: PRIV_ALARMACK | J32: A_P1_SERV | M32: B201_GenSttFail_A | R32: C_LOPRI | S32: B201 | T32: Class_Process | U32: BR4_Cluster1 | X32: BR4.UTILITIES.WATER.WBBWD.B201
A33: BR4_Tags | B33: B201_LOS01_A | C33: Bore | D33: E-stop 01 Activated | E33: B201_LOS01_A | G33: CAT_P1 | I33: PRIV_ALARMACK | J33: A_P1_SERV | K33: E-stop 01 Activated | M33: B201_LOS01_A | R33: C_LOPRI | S33: B201 | T33: Class_Process | U33: BR4_Cluster1 | X33: BR4.UTILITIES.WATER.WBBWD.B201
A34: BR4_Tags | B34: B201_LOS02_A | C34: Bore | D34: E-stop 02 Activated | E34: B201_LOS02_A | G34: CAT_P1 | I34: PRIV_ALARMACK | J34: A_P1_SERV | K34: E-stop 02 Activated | M34: B201_LOS02_A | R34: C_LOPRI | S34: B201 | T34: Class_Process | U34: BR4_Cluster1 | X34: BR4.UTILITIES.WATER.WBBWD.B201
A35: BR4_Tags | B35: B201_LSL_A | C35: Bore | D35: Level Switch Low | E35: B201_LSL_A | G35: CAT_P3 | I35: PRIV_ALARMACK | J35: A_P1_SERV | M35: B201_LSL_A | R35: C_LOPRI | S35: B201 | T35: Class_Process | U35: BR4_Cluster1 | X35: BR4.UTILITIES.WATER.WBBWD.B201
A36: BR4_Tags | B36: B201_LT01_Lo_A | C36: Bore | D36: Level Low | E36: B201_LT01_Lo_A | G36: CAT_P3 | I36: PRIV_ALARMACK | J36: A_P1_SERV | M36: B201_LT01_Lo_A | R36: C_LOPRI | S36: B201 | T36: Class_Process | U36: BR4_Cluster1 | X36: BR4.UTILITIES.WATER.WBBWD.B201.LT01
A37: BR4_Tags | B37: B201_MC01_A | C37: Bore | D37: Main Contactor Fault | E37: B201_MC01_A | G37: CAT_P3 | I37: PRIV_ALARMACK | J37: A_P1_SERV | M37: B201_MC01_A | R37: C_LOPRI | S37: B201 | T37: Class_Process | U37: BR4_Cluster1 | X37: BR4.UTILITIES.WATER.WBBWD.B201.MC01
A38: BR4_Tags | B38: B305_PT01_Hi_A | C38: Bore | D38: Upstream Pressure Hi | E38: B305_PT01_Hi_A | G38: CAT_P3 | I38: PRIV_ALARMACK | J38: A_P1_SERV | M38: B305_PT01_Hi_A | R38: C_LOPRI | S38: B305 | T38: Class_Process | U38: BR4_Cluster1 | X38: BR4.UTILITIES.WATER.WBBWD.B305.PT01
A39: BR4_Tags | B39: B305_PT01_HiHi_A | C39: Bore | D39: Upstream Pressure HiHi | E39: B305_PT01_HiHi_A | G39: CAT_P3 | I39: PRIV_ALARMACK | J39: A_P1_SERV | M39: B305_PT01_HiHi_A | R39: C_LOPRI | S39: B305 | T39: Class_Process | U39: BR4_Cluster1 | X39: BR4.UTILITIES.WATER.WBBWD.B305.PT01
A40: BR4_Tags | B40: B305_PT02_Hi_A | C40: Bore | D40: Downstream Pressure Hi | E40: B305_PT02_Hi_A | G40: CAT_P3 | I40: PRIV_ALARMACK | J40: A_P1_SERV | M40: B305_PT02_Hi_A | R40: C_LOPRI | S40: B305 | T40: Class_Process | U40: BR4_Cluster1 | X40: BR4.UTILITIES.WATER.WBBWD.B305.PT02
A41: BR4_Tags | B41: B305_PT02_HiHi_A | C41: Bore | D41: Downstream Pressure HiHi | E41: B305_PT02_HiHi_A | G41: CAT_P3 | I41: PRIV_ALARMACK | J41: A_P1_SERV | M41: B305_PT02_HiHi_A | R41: C_LOPRI | S41: B305 | T41: Class_Process | U41: BR4_Cluster1 | X41: BR4.UTILITIES.WATER.WBBWD.B305.PT02
A42: BR4_Tags | B42: B304_PT01_Hi_A | C42: Bore | D42: Upstream Pressure Hi | E42: B304_PT01_Hi_A | G42: CAT_P3 | I42: PRIV_ALARMACK | J42: A_P1_SERV | M42: B304_PT01_Hi_A | R42: C_LOPRI | S42: B304 | T42: Class_Process | U42: BR4_Cluster1 | X42: BR4.UTILITIES.WATER.WBBWD.B304.PT01
A43: BR4_Tags | B43: B304_PT01_HiHi_A | C43: Bore | D43: Upstream Pressure HiHi | E43: B304_PT01_HiHi_A | G43: CAT_P3 | I43: PRIV_ALARMACK | J43: A_P1_SERV | M43: B304_PT01_HiHi_A | R43: C_LOPRI | S43: B304 | T43: Class_Process | U43: BR4_Cluster1 | X43: BR4.UTILITIES.WATER.WBBWD.B304.PT01
...
